Workbook

Sheet DA 1
BR1: =COUNTIF(BR4:BR285,"True") -> 69 | BS1: =COUNTIF(BS4:BS285,"True") -> 76 | BT1: =COUNTIF(BT4:BT285,"True") -> 57 | BU1: =COUNTIF(BU4:BU285,"True") -> 67 | BV1: =COUNTIF(BV4:BV285,"True") -> 61 | BW1: =COUNTIF(BW4:BW285,"True") -> 58
A2: Name | B2: Email | C2: Phone | D2: Centre | E2: Total Classes | F2: Class attended | G2: Percentage | H2: Total Class without shift 2 | I2: Class Attended without shift 2 | J2: Percentage without shift 2 | L2: 46096 | M2: 46095 | N2: 46089 | O2: 46088 | P2: 46082 | Q2: 46081 | R2: 46075 | S2: 46074 | T2: 46068 | U2: 46067 | V2: 46067 | W2: 46061 | X2: 46060 | Y2: 46060 | Z2: 46054 | AA2: 46053 | AB2: 46053 | AC2: 46047 | AD2: 46046 | AE2: 46046 | AF2: 45675 | AG2: 45674 | AH2: 45674 | AI2: 45667 | AJ2: 45661 | AK2: 46025 | AL2: 46012 | AM2: 46005 | AN2: 46004 | AO2: 46004 | AP2: 45998 | AQ2: 45997 | AR2: 45997 | AS2: 45991 | AT2: 45990 | AU2: 45990 | AV2: 45984 | AW2: 45983 | AX2: 45983 | AY2: 45977 | AZ2: 45976 | BA2: 45976 | BB2: 45970 | BC2: 45969 | BD2: 45963 | BE2: 45962 | BF2: 45955 | BG2: 45955 | BH2: 45942 | BI2: 45941 | BJ2: 45941 | BK2: 45935 | BL2: 45934 | BM2: 45934 | BN2: 45928 | BO2: 45927 | BP2: 45921 | BQ2: 45920 | BR2: 45914 | BS2: 45913 | BT2: 45907 | BU2: 45906 | BV2: 31-Aug-2025 | BW2: 30-Aug-2025
U3: Shift 2 | X3: Shift 2 | AA3: Shift 2 | AD3: Shift 2 | AG3: Shift 2 | AI3: Shift 2 | AN3: Shift 2 | AO3: Shift 1 | AQ3: Shift 2 | AR3: Shift 1 | AT3: Shift 2 | AU3: Shift 1 | AW3: Shift 2 | AX3: Shift 1 | AY3: Shift 1 | AZ3: Shift 2 | BA3: Shift 1 | BB3: Shift 1 | BC3: Shift 2 | BD3: Shift 1 | BE3: Shift 1 | BF3: Shift 2 | BG3: Shift 1 | BH3: Shift 1 | BI3: Shift 2 | BJ3: Shift 1 | BK3: Shift 1 | BL3: Shift 2 | BM3: Shift 1 | BN3: Shift 1 | BO3: Shift 1 | BP3: Shift 1 | BQ3: Shift 1 | BR3: Shift 1 | BS3: Shift 1 | BT3: Shift 1 | BU3: Shift 1 | BV3: Shift 1 | BW3: Shift 1
A4: S R AdithyaR Adithya | B4: N.A. | C4: 7019560434 | BT4: FALSE | BU4: FALSE | BV4: FALSE | BW4: FALSE | BX4: =COUNTA(AS4:BW4) -> 4 | BY4: =COUNTIF(AS4:BW4,TRUE) -> 0 | BZ4: =BY4/BX4 -> 0 | CA4: =IF(BZ4>=0.6,"GOOD IN NOV","BAD IN NOV") -> BAD IN NOV | CB4: =COUNTA(AM4:BW4) -> 4 | CC4: =COUNTIF(AM4:BW4,TRUE) -> 0 | CD4: =CC4/CB4 -> 0 | CE4: =if(CD4>=0.4,"Good in dec","Bad in dec") -> Bad in dec | CF4: =IF(AND(CA4="GOOD IN NOV",CE4="Bad in dec"),"CONNECT","NOT CONNECT") -> NOT CONNECT
A5: Furquan mohammed | B5: furquanmohammedadhoni@gmail.com | C5: 9916346376 | D5: Bengalore | BT5: FALSE | BU5: FALSE | BV5: FALSE | BW5: FALSE | BX5: =COUNTA(AS5:BW5) -> 4 | BY5: =COUNTIF(AS5:BW5,TRUE) -> 0 | BZ5: =BY5/BX5 -> 0 | CA5: =IF(BZ5>=0.6,"GOOD IN NOV","BAD IN NOV") -> BAD IN NOV | CB5: =COUNTA(AM5:BW5) -> 4 | CC5: =COUNTIF(AM5:BW5,TRUE) -> 0 | CD5: =CC5/CB5 -> 0 | CE5: =if(CD5>=0.4,"Good in dec","Bad in dec") -> Bad in dec | CF5: =IF(AND(CA5="GOOD IN NOV",CE5="Bad in dec"),"CONNECT","NOT CONNECT") -> NOT CONNECT
A6: Abhishek Shikhre | B6: abhishikhare1111@gmail.com | C6: 9589934248 | D6: Indore | E6: =COUNTIF($K6:CF6,TRUE) + COUNTIF($K6:CF6,FALSE) -> 64 | F6: =COUNTIF($K6:CF6,TRUE) -> 41 | G6: =ROUND((F6/E6)*100,0) -> 64 | H6: =COUNTIF(K6:CF6,TRUE)+COUNTIF(K6:CF6,FALSE)-COUNTIF($K$3:CF$3,"Shift 2") -> 49 | I6: =F6- COUNTIFS($K6:CF6,"TRUE",$K$3:CF$3,"Shift 2") -> 38 | J6: =(I6/H6)*100 -> 77.55102 | L6: FALSE | M6: TRUE | N6: FALSE | O6: TRUE | P6: TRUE | Q6: TRUE | R6: FALSE | S6: TRUE | T6: TRUE | U6: FALSE | V6: TRUE | W6: FALSE | X6: FALSE | Y6: TRUE | Z6: TRUE | AA6: TRUE | AB6: TRUE | AC6: TRUE | AD6: FALSE | AE6: TRUE | AF6: FALSE | AG6: FALSE | AH6: TRUE | AI6: FALSE | AJ6: FALSE | AK6: TRUE | AL6: TRUE | AM6: TRUE | AN6: FALSE | AO6: TRUE | AP6: TRUE | AQ6: FALSE | AR6: TRUE | AS6: FALSE | AT6: FALSE | AU6: TRUE | AV6: TRUE | AW6: FALSE | AX6: TRUE | AY6: TRUE | AZ6: FALSE | BA6: TRUE | BB6: TRUE | BC6: FALSE | BD6: FALSE | BE6: TRUE | BF6: TRUE | BG6: TRUE | BH6: TRUE | BI6: FALSE | BJ6: TRUE | BK6: FALSE | BL6: TRUE | BM6: TRUE | BN6: TRUE | BO6: TRUE | BP6: FALSE | BQ6: TRUE | BR6: TRUE | BS6: TRUE | BT6: FALSE | BU6: TRUE | BV6: TRUE | BW6: TRUE | BX6: =COUNTA(AS6:BW6) -> 31 | BY6: =COUNTIF(AS6:BW6,TRUE) -> 21 | BZ6: =BY6/BX6 -> 0.67741935 | CA6: =IF(BZ6>=0.6,"GOOD IN NOV","BAD IN NOV") -> GOOD IN NOV | CB6: =COUNTA(AM6:BW6) -> 37 | CC6: =COUNTIF(AM6:BW6,TRUE) -> 25 | CD6: =CC6/CB6 -> 0.67567568 | CE6: =if(CD6>=0.4,"Good in dec","Bad in dec") -> Good in dec | CF6: =IF(AND(CA6="GOOD IN NOV",CE6="Bad in dec"),"CONNECT","NOT CONNECT") -> NOT CONNECT
A7: Ajay Banait | B7: ajaybanait5@gmail.com | C7: 7440262005 | D7: Indore | E7: =COUNTIF($K7:CF7,TRUE) + COUNTIF($K7:CF7,FALSE) -> 64 | F7: =COUNTIF($K7:CF7,TRUE) -> 50 | G7: =ROUND((F7/E7)*100,0) -> 78 | H7: =COUNTIF(K7:CF7,TRUE)+COUNTIF(K7:CF7,FALSE)-COUNTIF($K$3:CF$3,"Shift 2") -> 49 | I7: =F7- COUNTIFS($K7:CF7,"TRUE",$K$3:CF$3,"Shift 2") -> 41 | J7: =(I7/H7)*100 -> 83.673469 | L7: TRUE | M7: FALSE | N7: TRUE | O7: FALSE | P7: TRUE | Q7: TRUE | R7: TRUE | S7: TRUE | T7: TRUE | U7: FALSE | V7: TRUE | W7: TRUE | X7: FALSE | Y7: FALSE | Z7: TRUE | AA7: FALSE | AB7: TRUE | AC7: TRUE | AD7: FALSE | AE7: FALSE | AF7: TRUE | AG7: TRUE | AH7: TRUE | AI7: TRUE | AJ7: TRUE | AK7: TRUE | AL7: TRUE | AM7: TRUE | AN7: FALSE | AO7: TRUE | AP7: TRUE | AQ7: FALSE | AR7: TRUE | AS7: TRUE | AT7: TRUE | AU7: TRUE | AV7: TRUE | AW7: TRUE | AX7: TRUE | AY7: TRUE | AZ7: TRUE | BA7: TRUE | BB7: TRUE | BC7: TRUE | BD7: TRUE | BE7: TRUE | BF7: TRUE | BG7: TRUE | BH7: TRUE | BI7: TRUE | BJ7: TRUE | BK7: TRUE | BL7: TRUE | BM7: TRUE | BN7: TRUE | BO7: TRUE | BP7: TRUE | BQ7: TRUE | BR7: TRUE | BS7: TRUE | BT7: FALSE | BU7: FALSE | BV7: FALSE | BW7: FALSE | BX7: =COUNTA(AS7:BW7) -> 31 | BY7: =COUNTIF(AS7:BW7,TRUE) -> 27 | BZ7: =BY7/BX7 -> 0.87096774 | CA7: =IF(BZ7>=0.6,"GOOD IN NOV","BAD IN NOV") -> GOOD IN NOV | CB7: =COUNTA(AM7:BW7) -> 37 | CC7: =COUNTIF(AM7:BW7,TRUE) -> 31 | CD7: =CC7/CB7 -> 0.83783784 | CE7: =if(CD7>=0.4,"Good in dec","Bad in dec") -> Good in dec | CF7: =IF(AND(CA7="GOOD IN NOV",CE7="Bad in dec"),"CONNECT","NOT CONNECT") -> NOT CONNECT
A8: Ankesh Maheshwari | B8: ankeshmaheshwari2002@gmail.com | C8: 7024157979 | D8: Indore | E8: =COUNTIF($K8:CF8,TRUE) + COUNTIF($K8:CF8,FALSE) -> 64 | F8: =COUNTIF($K8:CF8,TRUE) -> 52 | G8: =ROUND((F8/E8)*100,0) -> 81 | H8: =COUNTIF(K8:CF8,TRUE)+COUNTIF(K8:CF8,FALSE)-COUNTIF($K$3:CF$3,"Shift 2") -> 49 | I8: =F8- COUNTIFS($K8:CF8,"TRUE",$K$3:CF$3,"Shift 2") -> 43 | J8: =(I8/H8)*100 -> 87.755102 | L8: FALSE | M8: FALSE | N8: TRUE | O8: TRUE | P8: TRUE | Q8: TRUE | R8: TRUE | S8: TRUE | T8: TRUE | U8: FALSE | V8: TRUE | W8: TRUE | X8: FALSE | Y8: TRUE | Z8: TRUE | AA8: FALSE | AB8: TRUE | AC8: TRUE | AD8: FALSE | AE8: TRUE | AF8: TRUE | AG8: FALSE | AH8: FALSE | AI8: TRUE | AJ8: FALSE | AK8: TRUE | AL8: TRUE | AM8: TRUE | AN8: FALSE | AO8: TRUE | AP8: TRUE | AQ8: TRUE | AR8: TRUE | AS8: TRUE | AT8: TRUE | AU8: TRUE | AV8: TRUE | AW8: TRUE | AX8: TRUE | AY8: TRUE | AZ8: TRUE | BA8: TRUE | BB8: FALSE | BC8: TRUE | BD8: TRUE | BE8: TRUE | BF8: TRUE | BG8: TRUE | BH8: TRUE | BI8: TRUE | BJ8: TRUE | BK8: TRUE | BL8: TRUE | BM8: TRUE | BN8: TRUE | BO8: TRUE | BP8: TRUE | BQ8: TRUE | BR8: TRUE | BS8: TRUE | BT8: TRUE | BU8: TRUE | BV8: TRUE | BW8: FALSE | BX8: =COUNTA(AS8:BW8) -> 31 | BY8: =COUNTIF(AS8:BW8,TRUE) -> 29 | BZ8: =BY8/BX8 -> 0.93548387 | CA8: =IF(BZ8>=0.6,"GOOD IN NOV","BAD IN NOV") -> GOOD IN NOV | CB8: =COUNTA(AM8:BW8) -> 37 | CC8: =COUNTIF(AM8:BW8,TRUE) -> 34 | CD8: =CC8/CB8 -> 0.91891892 | CE8: =if(CD8>=0.4,"Good in dec","Bad in dec") -> Good in dec | CF8: =IF(AND(CA8="GOOD IN NOV",CE8="Bad in dec"),"CONNECT","NOT CONNECT") -> NOT CONNECT
A9: Bhagyashree Agrawal | B9: bhagyashreeagrawal5@gmail.com | C9: 7240912177 | D9: Indore | E9: =COUNTIF($K9:CF9,TRUE) + COUNTIF($K9:CF9,FALSE) -> 64 | F9: =COUNTIF($K9:CF9,TRUE) -> 40 | G9: =ROUND((F9/E9)*100,0) -> 63 | H9: =COUNTIF(K9:CF9,TRUE)+COUNTIF(K9:CF9,FALSE)-COUNTIF($K$3:CF$3,"Shift 2") -> 49 | I9: =F9- COUNTIFS($K9:CF9,"TRUE",$K$3:CF$3,"Shift 2") -> 37 | J9: =(I9/H9)*100 -> 75.510204 | L9: TRUE | M9: TRUE | N9: TRUE | O9: FALSE | P9: TRUE | Q9: FALSE | R9: TRUE | S9: FALSE | T9: TRUE | U9: FALSE | V9: TRUE | W9: TRUE | X9: FALSE | Y9: TRUE | Z9: FALSE | AA9: FALSE | AB9: TRUE | AC9: TRUE | AD9: FALSE | AE9: TRUE | AF9: TRUE | AG9: FALSE | AH9: TRUE | AI9: FALSE | AJ9: TRUE | AK9: TRUE | AL9: TRUE | AM9: TRUE | AN9: FALSE | AO9: TRUE | AP9: TRUE | AQ9: FALSE | AR9: TRUE | AS9: TRUE | AT9: FALSE | AU9: TRUE | AV9: FALSE | AW9: FALSE | AX9: FALSE | AY9: TRUE | AZ9: FALSE | BA9: TRUE | BB9: TRUE | BC9: FALSE | BD9: TRUE | BE9: FALSE | BF9: TRUE | BG9: TRUE | BH9: TRUE | BI9: TRUE | BJ9: TRUE | BK9: TRUE | BL9: TRUE | BM9: TRUE | BN9: FALSE | BO9: TRUE | BP9: TRUE | BQ9: TRUE | BR9: TRUE | BS9: TRUE | BT9: FALSE | BU9: FALSE | BV9: FALSE | BW9: FALSE | BX9: =COUNTA(AS9:BW9) -> 31 | BY9: =COUNTIF(AS9:BW9,TRUE) -> 19 | BZ9: =BY9/BX9 -> 0.61290323 | CA9: =IF(BZ9>=0.6,"GOOD IN NOV","BAD IN NOV") -> GOOD IN NOV | CB9: =COUNTA(AM9:BW9) -> 37 | CC9: =COUNTIF(AM9:BW9,TRUE) -> 23 | CD9: =CC9/CB9 -> 0.62162162 | CE9: =if(CD9>=0.4,"Good in dec","Bad in dec") -> Good in dec | CF9: =IF(AND(CA9="GOOD IN NOV",CE9="Bad in dec"),"CONNECT","NOT CONNECT") -> NOT CONNECT
A10: Durgesh Suryawanshi | B10: Thoratdurgesh5@gmail.com | C10: 9165262620 | D10: Indore | E10: =COUNTIF($K10:CF10,TRUE) + COUNTIF($K10:CF10,FALSE) -> 64 | F10: =COUNTIF($K10:CF10,TRUE) -> 1 | G10: =ROUND((F10/E10)*100,0) -> 2 | H10: =COUNTIF(K10:CF10,TRUE)+COUNTIF(K10:CF10,FALSE)-COUNTIF($K$3:CF$3,"Shift 2") -> 49 | I10: =F10- COUNTIFS($K10:CF10,"TRUE",$K$3:CF$3,"Shift 2") -> 1 | J10: =(I10/H10)*100 -> 2.0408163 | L10: FALSE | M10: FALSE | N10: FALSE | O10: FALSE | P10: FALSE | Q10: FALSE | R10: FALSE | S10: FALSE | T10: FALSE | U10: FALSE | V10: FALSE | W10: FALSE | X10: FALSE | Y10: FALSE | Z10: FALSE | AA10: FALSE | AB10: FALSE | AC10: FALSE | AD10: FALSE | AE10: FALSE | AF10: FALSE | AG10: FALSE | AH10: FALSE | AI10: FALSE | AJ10: FALSE | AK10: FALSE | AL10: FALSE | AM10: FALSE | AN10: FALSE | AO10: FALSE | AP10: FALSE | AQ10: FALSE | AR10: FALSE | AS10: FALSE | AT10: FALSE | AU10: FALSE | AV10: FALSE | AW10: FALSE | AX10: FALSE | AY10: FALSE | AZ10: FALSE | BA10: FALSE | BB10: FALSE | BC10: FALSE | BD10: FALSE | BE10: FALSE | BF10: FALSE | BG10: FALSE | BH10: FALSE | BI10: FALSE | BJ10: FALSE | BK10: FALSE | BL10: FALSE | BM10: FALSE | BN10: FALSE | BO10: FALSE | BP10: FALSE | BQ10: FALSE | BR10: FALSE | BS10: FALSE | BT10: FALSE | BU10: TRUE | BV10: FALSE | BW10: FALSE | BX10: =COUNTA(AS10:BW10) -> 31 | BY10: =COUNTIF(AS10:BW10,TRUE) -> 1 | BZ10: =BY10/BX10 -> 0.032258065 | CA10: =IF(BZ10>=0.6,"GOOD IN NOV","BAD IN NOV") -> BAD IN NOV | CB10: =COUNTA(AM10:BW10) -> 37 | CC10: =COUNTIF(AM10:BW10,TRUE) -> 1 | CD10: =CC10/CB10 -> 0.027027027 | CE10: =if(CD10>=0.4,"Good in dec","Bad in dec") -> Bad in dec | CF10: =IF(AND(CA10="GOOD IN NOV",CE10="Bad in dec"),"CONNECT","NOT CONNECT") -> NOT CONNECT
A11: Harshit Sharma | B11: harshitsharma881549@gmail.com | C11: 7415805759 | D11: Indore | E11: =COUNTIF($K11:CF11,TRUE) + COUNTIF($K11:CF11,FALSE) -> 64 | F11: =COUNTIF($K11:CF11,TRUE) -> 38 | G11: =ROUND((F11/E11)*100,0) -> 59 | H11: =COUNTIF(K11:CF11,TRUE)+COUNTIF(K11:CF11,FALSE)-COUNTIF($K$3:CF$3,"Shift 2") -> 49 | I11: =F11- COUNTIFS($K11:CF11,"TRUE",$K$3:CF$3,"Shift 2") -> 32 | J11: =(I11/H11)*100 -> 65.306122 | L11: FALSE | M11: FALSE | N11: TRUE | O11: FALSE | P11: FALSE | Q11: FALSE | R11: TRUE | S11: FALSE | T11: FALSE | U11: FALSE | V11: FALSE | W11: FALSE | X11: FALSE | Y11: FALSE | Z11: FALSE | AA11: FALSE | AB11: FALSE | AC11: FALSE | AD11: FALSE | AE11: FALSE | AF11: TRUE | AG11: TRUE | AH11: TRUE | AI11: FALSE | AJ11: TRUE | AK11: TRUE | AL11: TRUE | AM11: TRUE | AN11: FALSE | AO11: TRUE | AP11: TRUE | AQ11: FALSE | AR11: TRUE | AS11: TRUE | AT11: FALSE | AU11: TRUE | AV11: FALSE | AW11: FALSE | AX11: FALSE | AY11: TRUE | AZ11: TRUE | BA11: TRUE | BB11: TRUE | BC11: TRUE | BD11: TRUE | BE11: TRUE | BF11: TRUE | BG11: TRUE | BH11: TRUE | BI11: TRUE | BJ11: TRUE | BK11: TRUE | BL11: TRUE | BM11: TRUE | BN11: TRUE | BO11: TRUE | BP11: FALSE | BQ11: TRUE | BR11: TRUE | BS11: TRUE | BT11: TRUE | BU11: TRUE | BV11: TRUE | BW11: TRUE | BX11: =COUNTA(AS11:BW11) -> 31 | BY11: =COUNTIF(AS11:BW11,TRUE) -> 26 | BZ11: =BY11/BX11 -> 0.83870968 | CA11: =IF(BZ11>=0.6,"GOOD IN NOV","BAD IN NOV") -> GOOD IN NOV | CB11: =COUNTA(AM11:BW11) -> 37 | CC11: =COUNTIF(AM11:BW11,TRUE) -> 30 | CD11: =CC11/CB11 -> 0.81081081 | CE11: =if(CD11>=0.4,"Good in dec","Bad in dec") -> Good in dec | CF11: =IF(AND(CA11="GOOD IN NOV",CE11="Bad in dec"),"CONNECT","NOT CONNECT") -> NOT CONNECT
A12: Jay Varandani | B12: jayvarandani123@gmail.com | C12: 8109414954 | D12: Indore | E12: =COUNTIF($K12:CF12,TRUE) + COUNTIF($K12:CF12,FALSE) -> 64 | F12: =COUNTIF($K12:CF12,TRUE) -> 23 | G12: =ROUND((F12/E12)*100,0) -> 36 | H12: =COUNTIF(K12:CF12,TRUE)+COUNTIF(K12:CF12,FALSE)-COUNTIF($K$3:CF$3,"Shift 2") -> 49 | I12: =F12- COUNTIFS($K12:CF12,"TRUE",$K$3:CF$3,"Shift 2") -> 22 | J12: =(I12/H12)*100 -> 44.897959 | L12: FALSE | M12: FALSE | N12: FALSE | O12: FALSE | P12: FALSE | Q12: FALSE | R12: FALSE | S12: FALSE | T12: FALSE | U12: FALSE | V12: FALSE | W12: FALSE | X12: FALSE | Y12: FALSE | Z12: FALSE | AA12: FALSE | AB12: FALSE | AC12: TRUE | AD12: FALSE | AE12: FALSE | AF12: TRUE | AG12: FALSE | AH12: TRUE | AI12: FALSE | AJ12: TRUE | AK12: TRUE | AL12: TRUE | AM12: FALSE | AN12: FALSE | AO12: FALSE | AP12: TRUE | AQ12: FALSE | AR12: TRUE | AS12: FALSE | AT12: FALSE | AU12: TRUE | AV12: TRUE | AW12: FALSE | AX12: TRUE | AY12: TRUE | AZ12: FALSE | BA12: TRUE | BB12: FALSE | BC12: FALSE | BD12: TRUE | BE12: TRUE | BF12: FALSE | BG12: TRUE | BH12: FALSE | BI12: FALSE | BJ12: TRUE | BK12: FALSE | BL12: TRUE | BM12: TRUE | BN12: FALSE | BO12: FALSE | BP12: TRUE | BQ12: TRUE | BR12: TRUE | BS12: TRUE | BT12: FALSE | BU12: FALSE | BV12: FALSE | BW12: FALSE | BX12: =COUNTA(AS12:BW12) -> 31 | BY12: =COUNTIF(AS12:BW12,TRUE) -> 15 | BZ12: =BY12/BX12 -> 0.48387097 | CA12: =IF(BZ12>=0.6,"GOOD IN NOV","BAD IN NOV") -> BAD IN NOV | CB12: =COUNTA(AM12:BW12) -> 37 | CC12: =COUNTIF(AM12:BW12,TRUE) -> 17 | CD12: =CC12/CB12 -> 0.45945946 | CE12: =if(CD12>=0.4,"Good in dec","Bad in dec") -> Good in dec | CF12: =IF(AND(CA12="GOOD IN NOV",CE12="Bad in dec"),"CONNECT","NOT CONNECT") -> NOT CONNECT
A13: Kuldeep Rathore | B13: kuldeeprathore9440@gmail.com | C13: 7389634306 | D13: Indore | E13: =COUNTIF($K13:CF13,TRUE) + COUNTIF($K13:CF13,FALSE) -> 64 | F13: =COUNTIF($K13:CF13,TRUE) -> 42 | G13: =ROUND((F13/E13)*100,0) -> 66 | H13: =COUNTIF(K13:CF13,TRUE)+COUNTIF(K13:CF13,FALSE)-COUNTIF($K$3:CF$3,"Shift 2") -> 49 | I13: =F13- COUNTIFS($K13:CF13,"TRUE",$K$3:CF$3,"Shift 2") -> 40 | J13: =(I13/H13)*100 -> 81.632653 | L13: TRUE | M13: TRUE | N13: TRUE | O13: TRUE | P13: TRUE | Q13: TRUE | R13: FALSE | S13: FALSE | T13: TRUE | U13: FALSE | V13: TRUE | W13: TRUE | X13: FALSE | Y13: TRUE | Z13: FALSE | AA13: TRUE | AB13: TRUE | AC13: TRUE | AD13: FALSE | AE13: TRUE | AF13: TRUE | AG13: FALSE | AH13: TRUE | AI13: FALSE | AJ13: TRUE | AK13: TRUE | AL13: TRUE | AM13: TRUE | AN13: FALSE | AO13: TRUE | AP13: TRUE | AQ13: FALSE | AR13: TRUE | AS13: TRUE | AT13: FALSE | AU13: TRUE | AV13: TRUE | AW13: FALSE | AX13: TRUE | AY13: FALSE | AZ13: FALSE | BA13: TRUE | BB13: FALSE | BC13: FALSE | BD13: FALSE | BE13: TRUE | BF13: FALSE | BG13: TRUE | BH13: TRUE | BI13: FALSE | BJ13: TRUE | BK13: FALSE | BL13: TRUE | BM13: TRUE | BN13: FALSE | BO13: TRUE | BP13: TRUE | BQ13: TRUE | BR13: TRUE | BS13: TRUE | BT13: FALSE | BU13: TRUE | BV13: TRUE | BW13: TRUE | BX13: =COUNTA(AS13:BW13) -> 31 | BY13: =COUNTIF(AS13:BW13,TRUE) -> 19 | BZ13: =BY13/BX13 -> 0.61290323 | CA13: =IF(BZ13>=0.6,"GOOD IN NOV","BAD IN NOV") -> GOOD IN NOV | CB13: =COUNTA(AM13:BW13) -> 37 | CC13: =COUNTIF(AM13:BW13,TRUE) -> 23 | CD13: =CC13/CB13 -> 0.62162162 | CE13: =if(CD13>=0.4,"Good in dec","Bad in dec") -> Good in dec | CF13: =IF(AND(CA13="GOOD IN NOV",CE13="Bad in dec"),"CONNECT","NOT CONNECT") -> NOT CONNECT
A14: Maitri Kashmiri | B14: maitrikashmiri@gmail.com | C14: 7691949111 | D14: Indore | E14: =COUNTIF($K14:CF14,TRUE) + COUNTIF($K14:CF14,FALSE) -> 64 | F14: =COUNTIF($K14:CF14,TRUE) -> 0 | G14: =ROUND((F14/E14)*100,0) -> 0 | H14: =COUNTIF(K14:CF14,TRUE)+COUNTIF(K14:CF14,FALSE)-COUNTIF($K$3:CF$3,"Shift 2") -> 49 | I14: =F14- COUNTIFS($K14:CF14,"TRUE",$K$3:CF$3,"Shift 2") -> 0 | J14: =(I14/H14)*100 -> 0 | L14: FALSE | M14: FALSE | N14: FALSE | O14: FALSE | P14: FALSE | Q14: FALSE | R14: FALSE | S14: FALSE | T14: FALSE | U14: FALSE | V14: FALSE | W14: FALSE | X14: FALSE | Y14: FALSE | Z14: FALSE | AA14: FALSE | AB14: FALSE | AC14: FALSE | AD14: FALSE | AE14: FALSE | AF14: FALSE | AG14: FALSE | AH14: FALSE | AI14: FALSE | AJ14: FALSE | AK14: FALSE | AL14: FALSE | AM14: FALSE | AN14: FALSE | AO14: FALSE | AP14: FALSE | AQ14: FALSE | AR14: FALSE | AS14: FALSE | AT14: FALSE | AU14: FALSE | AV14: FALSE | AW14: FALSE | AX14: FALSE | AY14: FALSE | AZ14: FALSE | BA14: FALSE | BB14: FALSE | BC14: FALSE | BD14: FALSE | BE14: FALSE | BF14: FALSE | BG14: FALSE | BH14: FALSE | BI14: FALSE | BJ14: FALSE | BK14: FALSE | BL14: FALSE | BM14: FALSE | BN14: FALSE | BO14: FALSE | BP14: FALSE | BQ14: FALSE | BR14: FALSE | BS14: FALSE | BT14: FALSE | BU14: FALSE | BV14: FALSE | BW14: FALSE | BX14: =COUNTA(AS14:BW14) -> 31 | BY14: =COUNTIF(AS14:BW14,TRUE) -> 0 | BZ14: =BY14/BX14 -> 0 | CA14: =IF(BZ14>=0.6,"GOOD IN NOV","BAD IN NOV") -> BAD IN NOV | CB14: =COUNTA(AM14:BW14) -> 37 | CC14: =COUNTIF(AM14:BW14,TRUE) -> 0 | CD14: =CC14/CB14 -> 0 | CE14: =if(CD14>=0.4,"Good in dec","Bad in dec") -> Bad in dec | CF14: =IF(AND(CA14="GOOD IN NOV",CE14="Bad in dec"),"CONNECT","NOT CONNECT") -> NOT CONNECT
A15: Mayank Asahiya | B15: mayankasahiya27@gmail.com | C15: 8815188336 | D15: Indore | E15: =COUNTIF($K15:CF15,TRUE) + COUNTIF($K15:CF15,FALSE) -> 64 | F15: =COUNTIF($K15:CF15,TRUE) -> 38 | G15: =ROUND((F15/E15)*100,0) -> 59 | H15: =COUNTIF(K15:CF15,TRUE)+COUNTIF(K15:CF15,FALSE)-COUNTIF($K$3:CF$3,"Shift 2") -> 49 | I15: =F15- COUNTIFS($K15:CF15,"TRUE",$K$3:CF$3,"Shift 2") -> 32 | J15: =(I15/H15)*100 -> 65.306122 | L15: FALSE | M15: FALSE | N15: FALSE | O15: FALSE | P15: TRUE | Q15: TRUE | R15: FALSE | S15: FALSE | T15: FALSE | U15: FALSE | V15: FALSE | W15: FALSE | X15: FALSE | Y15: FALSE | Z15: TRUE | AA15: FALSE | AB15: TRUE | AC15: FALSE | AD15: FALSE | AE15: FALSE | AF15: TRUE | AG15: FALSE | AH15: TRUE | AI15: TRUE | AJ15: TRUE | AK15: TRUE | AL15: TRUE | AM15: TRUE | AN15: FALSE | AO15: TRUE | AP15: TRUE | AQ15: FALSE | AR15: TRUE | AS15: TRUE | AT15: FALSE | AU15: TRUE | AV15: FALSE | AW15: FALSE | AX15: FALSE | AY15: TRUE | AZ15: TRUE | BA15: TRUE | BB15: FALSE | BC15: TRUE | BD15: TRUE | BE15: TRUE | BF15: TRUE | BG15: TRUE | BH15: TRUE | BI15: TRUE | BJ15: TRUE | BK15: TRUE | BL15: TRUE | BM15: TRUE | BN15: TRUE | BO15: TRUE | BP15: TRUE | BQ15: FALSE | BR15: TRUE | BS15: TRUE | BT15: TRUE | BU15: TRUE | BV15: FALSE | BW15: TRUE | BX15: =COUNTA(AS15:BW15) -> 31 | BY15: =COUNTIF(AS15:BW15,TRUE) -> 24 | BZ15: =BY15/BX15 -> 0.77419355 | CA15: =IF(BZ15>=0.6,"GOOD IN NOV","BAD IN NOV") -> GOOD IN NOV | CB15: =COUNTA(AM15:BW15) -> 37 | CC15: =COUNTIF(AM15:BW15,TRUE) -> 28 | CD15: =CC15/CB15 -> 0.75675676 | CE15: =if(CD15>=0.4,"Good in dec","Bad in dec") -> Good in dec | CF15: =IF(AND(CA15="GOOD IN NOV",CE15="Bad in dec"),"CONNECT","NOT CONNECT") -> NOT CONNECT
A16: Mokshini Baglekar | B16: Mokshinibaglekar@gmail.com | C16: 9301892983 | D16: Indore | E16: =COUNTIF($K16:CF16,TRUE) + COUNTIF($K16:CF16,FALSE) -> 64 | F16: =COUNTIF($K16:CF16,TRUE) -> 18 | G16: =ROUND((F16/E16)*100,0) -> 28 | H16: =COUNTIF(K16:CF16,TRUE)+COUNTIF(K16:CF16,FALSE)-COUNTIF($K$3:CF$3,"Shift 2") -> 49 | I16: =F16- COUNTIFS($K16:CF16,"TRUE",$K$3:CF$3,"Shift 2") -> 15 | J16: =(I16/H16)*100 -> 30.612245 | L16: FALSE | M16: FALSE | N16: FALSE | O16: FALSE | P16: FALSE | Q16: FALSE | R16: FALSE | S16: FALSE | T16: FALSE | U16: FALSE | V16: FALSE | W16: FALSE | X16: FALSE | Y16: FALSE | Z16: FALSE | AA16: FALSE | AB16: FALSE | AC16: FALSE | AD16: FALSE | AE16: FALSE | AF16: FALSE | AG16: FALSE | AH16: FALSE | AI16: FALSE | AJ16: FALSE | AK16: FALSE | AL16: FALSE | AM16: TRUE | AN16: FALSE | AO16: TRUE | AP16: FALSE | AQ16: FALSE | AR16: FALSE | AS16: FALSE | AT16: FALSE | AU16: FALSE | AV16: TRUE | AW16: FALSE | AX16: TRUE | AY16: TRUE | AZ16: FALSE | BA16: TRUE | BB16: TRUE | BC16: FALSE | BD16: FALSE | BE16: TRUE | BF16: TRUE | BG16: TRUE | BH16: TRUE | BI16: TRUE | BJ16: TRUE | BK16: TRUE | BL16: TRUE | BM16: TRUE | BN16: FALSE | BO16: FALSE | BP16: TRUE | BQ16: TRUE | BR16: FALSE | BS16: FALSE | BT16: FALSE | BU16: FALSE | BV16: FALSE | BW16: FALSE | BX16: =COUNTA(AS16:BW16) -> 31 | BY16: =COUNTIF(AS16:BW16,TRUE) -> 16 | BZ16: =BY16/BX16 -> 0.51612903 | CA16: =IF(BZ16>=0.6,"GOOD IN NOV","BAD IN NOV") -> BAD IN NOV | CB16: =COUNTA(AM16:BW16) -> 37 | CC16: =COUNTIF(AM16:BW16,TRUE) -> 18 | CD16: =CC16/CB16 -> 0.48648649 | CE16: =if(CD16>=0.4,"Good in dec","Bad in dec") -> Good in dec | CF16: =IF(AND(CA16="GOOD IN NOV",CE16="Bad in dec"),"CONNECT","NOT CONNECT") -> NOT CONNECT
A17: Monu Singh | B17: monumonu7691mo@gmail.com | C17: 7691903352 | D17: Indore | E17: =COUNTIF($K17:CF17,TRUE) + COUNTIF($K17:CF17,FALSE) -> 64 | F17: =COUNTIF($K17:CF17,TRUE) -> 57 | G17: =ROUND((F17/E17)*100,0) -> 89 | H17: =COUNTIF(K17:CF17,TRUE)+COUNTIF(K17:CF17,FALSE)-COUNTIF($K$3:CF$3,"Shift 2") -> 49 | I17: =F17- COUNTIFS($K17:CF17,"TRUE",$K$3:CF$3,"Shift 2") -> 49 | J17: =(I17/H17)*100 -> 100 | L17: TRUE | M17: TRUE | N17: TRUE | O17: TRUE | P17: TRUE | Q17: TRUE | R17: TRUE | S17: TRUE | T17: TRUE | U17: FALSE | V17: TRUE | W17: TRUE | X17: FALSE | Y17: TRUE | Z17: TRUE | AA17: TRUE | AB17: TRUE | AC17: TRUE | AD17: FALSE | AE17: TRUE | AF17: TRUE | AG17: FALSE | AH17: TRUE | AI17: FALSE | AJ17: TRUE | AK17: TRUE | AL17: TRUE | AM17: TRUE | AN17: FALSE | AO17: TRUE | AP17: TRUE | AQ17: FALSE | AR17: TRUE | AS17: TRUE | AT17: TRUE | AU17: TRUE | AV17: TRUE | AW17: TRUE | AX17: TRUE | AY17: TRUE | AZ17: TRUE | BA17: TRUE | BB17: TRUE | BC17: TRUE | BD17: TRUE | BE17: TRUE | BF17: TRUE | BG17: TRUE | BH17: TRUE | BI17: TRUE | BJ17: TRUE | BK17: TRUE | BL17: TRUE | BM17: TRUE | BN17: TRUE | BO17: TRUE | BP17: TRUE | BQ17: TRUE | BR17: TRUE | BS17: TRUE | BT17: TRUE | BU17: TRUE | BV17: TRUE | BW17: TRUE | BX17: =COUNTA(AS17:BW17) -> 31 | BY17: =COUNTIF(AS17:BW17,TRUE) -> 31 | BZ17: =BY17/BX17 -> 1 | CA17: =IF(BZ17>=0.6,"GOOD IN NOV","BAD IN NOV") -> GOOD IN NOV | CB17: =COUNTA(AM17:BW17) -> 37 | CC17: =COUNTIF(AM17:BW17,TRUE) -> 35 | CD17: =CC17/CB17 -> 0.94594595 | CE17: =if(CD17>=0.4,"Good in dec","Bad in dec") -> Good in dec | CF17: =IF(AND(CA17="GOOD IN NOV",CE17="Bad in dec"),"CONNECT","NOT CONNECT") -> NOT CONNECT
A18: Nayan Malviya | B18: nayanranawat78@gmail.com | C18: 9098904715 | D18: Indore | E18: =COUNTIF($K18:CF18,TRUE) + COUNTIF($K18:CF18,FALSE) -> 62 | F18: =COUNTIF($K18:CF18,TRUE) -> 38 | G18: =ROUND((F18/E18)*100,0) -> 61 | H18: =COUNTIF(K18:CF18,TRUE)+COUNTIF(K18:CF18,FALSE)-COUNTIF($K$3:CF$3,"Shift 2") -> 47 | I18: =F18- COUNTIFS($K18:CF18,"TRUE",$K$3:CF$3,"Shift 2") -> 34 | J18: =(I18/H18)*100 -> 72.340426 | L18: TRUE | M18: TRUE | N18: TRUE | O18: FALSE | P18: TRUE | Q18: TRUE | R18: FALSE | S18: TRUE | T18: FALSE | U18: FALSE | V18: TRUE | W18: TRUE | X18: FALSE | Y18: TRUE | Z18: TRUE | AA18: TRUE | AB18: TRUE | AC18: FALSE | AD18: FALSE | AE18: FALSE | AF18: TRUE | AG18: FALSE | AH18: TRUE | AI18: FALSE | AJ18: TRUE | AK18: TRUE | AL18: TRUE | AM18: TRUE | AN18: FALSE | AO18: TRUE | AP18: TRUE | AQ18: FALSE | AR18: TRUE | AS18: TRUE | AT18: FALSE | AU18: TRUE | AV18: FALSE | AW18: TRUE | AX18: TRUE | AY18: TRUE | AZ18: TRUE | BA18: TRUE | BB18: TRUE | BC18: FALSE | BD18: TRUE | BE18: TRUE | BF18: FALSE | BG18: FALSE | BH18: TRUE | BI18: TRUE | BJ18: TRUE | BK18: FALSE | BL18: FALSE | BM18: FALSE | BN18: TRUE | BO18: TRUE | BP18: TRUE | BQ18: FALSE | BR18: FALSE | BS18: TRUE | BT18: FALSE | BU18: FALSE | BX18: =COUNTA(AS18:BW18) -> 29 | BY18: =COUNTIF(AS18:BW18,TRUE) -> 17 | BZ18: =BY18/BX18 -> 0.5862069 | CA18: =IF(BZ18>=0.6,"GOOD IN NOV","BAD IN NOV") -> BAD IN NOV | CB18: =COUNTA(AM18:BW18) -> 35 | CC18: =COUNTIF(AM18:BW18,TRUE) -> 21 | CD18: =CC18/CB18 -> 0.6 | CE18: =if(CD18>=0.4,"Good in dec","Bad in dec") -> Good in dec | CF18: =IF(AND(CA18="GOOD IN NOV",CE18="Bad in dec"),"CONNECT","NOT CONNECT") -> NOT CONNECT
A19: Piyush Tiwari | B19: piyushtiwari11041104@gmail.com | C19: 6265046873 | D19: Indore | E19: =COUNTIF($K19:CF19,TRUE) + COUNTIF($K19:CF19,FALSE) -> 64 | F19: =COUNTIF($K19:CF19,TRUE) -> 27 | G19: =ROUND((F19/E19)*100,0) -> 42 | H19: =COUNTIF(K19:CF19,TRUE)+COUNTIF(K19:CF19,FALSE)-COUNTIF($K$3:CF$3,"Shift 2") -> 49 | I19: =F19- COUNTIFS($K19:CF19,"TRUE",$K$3:CF$3,"Shift 2") -> 24 | J19: =(I19/H19)*100 -> 48.979592 | L19: FALSE | M19: FALSE | N19: FALSE | O19: FALSE | P19: FALSE | Q19: FALSE | R19: FALSE | S19: FALSE | T19: TRUE | U19: FALSE | V19: TRUE | W19: TRUE | X19: TRUE | Y19: TRUE | Z19: TRUE | AA19: TRUE | AB19: TRUE | AC19: FALSE | AD19: FALSE | AE19: TRUE | AF19: FALSE | AG19: FALSE | AH19: TRUE | AI19: FALSE | AJ19: TRUE | AK19: TRUE | AL19: FALSE | AM19: TRUE | AN19: FALSE | AO19: TRUE | AP19: TRUE | AQ19: FALSE | AR19: TRUE | AS19: FALSE | AT19: FALSE | AU19: TRUE | AV19: TRUE | AW19: FALSE | AX19: TRUE | AY19: TRUE | AZ19: FALSE | BA19: TRUE | BB19: TRUE | BC19: FALSE | BD19: FALSE | BE19: FALSE | BF19: TRUE | BG19: TRUE | BH19: FALSE | BI19: FALSE | BJ19: FALSE | BK19: FALSE | BL19: FALSE | BM19: FALSE | BN19: FALSE | BO19: FALSE | BP19: FALSE | BQ19: TRUE | BR19: TRUE | BS19: TRUE | BT19: FALSE | BU19: FALSE | BV19: FALSE | BW19: FALSE | BX19: =COUNTA(AS19:BW19) -> 31 | BY19: =COUNTIF(AS19:BW19,TRUE) -> 11 | BZ19: =BY19/BX19 -> 0.35483871 | CA19: =IF(BZ19>=0.6,"GOOD IN NOV","BAD IN NOV") -> BAD IN NOV | CB19: =COUNTA(AM19:BW19) -> 37 | CC19: =COUNTIF(AM19:BW19,TRUE) -> 15 | CD19: =CC19/CB19 -> 0.40540541 | CE19: =if(CD19>=0.4,"Good in dec","Bad in dec") -> Good in dec | CF19: =IF(AND(CA19="GOOD IN NOV",CE19="Bad in dec"),"CONNECT","NOT CONNECT") -> NOT CONNECT
A20: Prachi Patel | B20: prachipatel572002@gmail.com | C20: 9669099261 | D20: Indore | E20: =COUNTIF($K20:CF20,TRUE) + COUNTIF($K20:CF20,FALSE) -> 64 | F20: =COUNTIF($K20:CF20,TRUE) -> 42 | G20: =ROUND((F20/E20)*100,0) -> 66 | H20: =COUNTIF(K20:CF20,TRUE)+COUNTIF(K20:CF20,FALSE)-COUNTIF($K$3:CF$3,"Shift 2") -> 49 | I20: =F20- COUNTIFS($K20:CF20,"TRUE",$K$3:CF$3,"Shift 2") -> 38 | J20: =(I20/H20)*100 -> 77.55102 | L20: TRUE | M20: TRUE | N20: FALSE | O20: TRUE | P20: FALSE | Q20: TRUE | R20: TRUE | S20: TRUE | T20: TRUE | U20: FALSE | V20: TRUE | W20: TRUE | X20: FALSE | Y20: TRUE | Z20: TRUE | AA20: FALSE | AB20: TRUE | AC20: TRUE | AD20: FALSE | AE20: TRUE | AF20: TRUE | AG20: FALSE | AH20: TRUE | AI20: FALSE | AJ20: FALSE | AK20: TRUE | AL20: TRUE | AM20: TRUE | AN20: FALSE | AO20: TRUE | AP20: TRUE | AQ20: FALSE | AR20: TRUE | AS20: FALSE | AT20: FALSE | AU20: TRUE | AV20: FALSE | AW20: FALSE | AX20: TRUE | AY20: TRUE | AZ20: FALSE | BA20: FALSE | BB20: TRUE | BC20: TRUE | BD20: TRUE | BE20: TRUE | BF20: TRUE | BG20: TRUE | BH20: TRUE | BI20: TRUE | BJ20: TRUE | BK20: TRUE | BL20: TRUE | BM20: TRUE | BN20: FALSE | BO20: TRUE | BP20: TRUE | BQ20: TRUE | BR20: TRUE | BS20: TRUE | BT20: FALSE | BU20: FALSE | BV20: FALSE | BW20: FALSE | BX20: =COUNTA(AS20:BW20) -> 31 | BY20: =COUNTIF(AS20:BW20,TRUE) -> 20 | BZ20: =BY20/BX20 -> 0.64516129 | CA20: =IF(BZ20>=0.6,"GOOD IN NOV","BAD IN NOV") -> GOOD IN NOV | CB20: =COUNTA(AM20:BW20) -> 37 | CC20: =COUNTIF(AM20:BW20,TRUE) -> 24 | CD20: =CC20/CB20 -> 0.64864865 | CE20: =if(CD20>=0.4,"Good in dec","Bad in dec") -> Good in dec | CF20: =IF(AND(CA20="GOOD IN NOV",CE20="Bad in dec"),"CONNECT","NOT CONNECT") -> NOT CONNECT
A21: Priyanshu Patidar | B21: priyanshupatidar5619@gmail.com | C21: 7724016227 | D21: Indore | E21: =COUNTIF($K21:CF21,TRUE) + COUNTIF($K21:CF21,FALSE) -> 64 | F21: =COUNTIF($K21:CF21,TRUE) -> 50 | G21: =ROUND((F21/E21)*100,0) -> 78 | H21: =COUNTIF(K21:CF21,TRUE)+COUNTIF(K21:CF21,FALSE)-COUNTIF($K$3:CF$3,"Shift 2") -> 49 | I21: =F21- COUNTIFS($K21:CF21,"TRUE",$K$3:CF$3,"Shift 2") -> 44 | J21: =(I21/H21)*100 -> 89.795918 | L21: TRUE | M21: TRUE | N21: FALSE | O21: TRUE | P21: TRUE | Q21: TRUE | R21: FALSE | S21: FALSE | T21: TRUE | U21: FALSE | V21: TRUE | W21: TRUE | X21: FALSE | Y21: TRUE | Z21: TRUE | AA21: FALSE | AB21: FALSE | AC21: TRUE | AD21: FALSE | AE21: TRUE | AF21: TRUE | AG21: FALSE | AH21: TRUE | AI21: FALSE | AJ21: TRUE | AK21: TRUE | AL21: TRUE | AM21: TRUE | AN21: FALSE | AO21: TRUE | AP21: TRUE | AQ21: TRUE | AR21: TRUE | AS21: TRUE | AT21: TRUE | AU21: TRUE | AV21: TRUE | AW21: FALSE | AX21: FALSE | AY21: TRUE | AZ21: TRUE | BA21: TRUE | BB21: TRUE | BC21: TRUE | BD21: TRUE | BE21: TRUE | BF21: FALSE | BG21: TRUE | BH21: TRUE | BI21: TRUE | BJ21: TRUE | BK21: TRUE | BL21: TRUE | BM21: TRUE | BN21: TRUE | BO21: TRUE | BP21: TRUE | BQ21: TRUE | BR21: TRUE | BS21: TRUE | BT21: TRUE | BU21: TRUE | BV21: TRUE | BW21: TRUE | BX21: =COUNTA(AS21:BW21) -> 31 | BY21: =COUNTIF(AS21:BW21,TRUE) -> 28 | BZ21: =BY21/BX21 -> 0.90322581 | CA21: =IF(BZ21>=0.6,"GOOD IN NOV","BAD IN NOV") -> GOOD IN NOV | CB21: =COUNTA(AM21:BW21) -> 37 | CC21: =COUNTIF(AM21:BW21,TRUE) -> 33 | CD21: =CC21/CB21 -> 0.89189189 | CE21: =if(CD21>=0.4,"Good in dec","Bad in dec") -> Good in dec | CF21: =IF(AND(CA21="GOOD IN NOV",CE21="Bad in dec"),"CONNECT","NOT CONNECT") -> NOT CONNECT
A22: Raghav Mahajan | B22: raghavmahajan965@gmail.com | C22: 7566364655 | D22: Indore | E22: =COUNTIF($K22:CF22,TRUE) + COUNTIF($K22:CF22,FALSE) -> 64 | F22: =COUNTIF($K22:CF22,TRUE) -> 31 | G22: =ROUND((F22/E22)*100,0) -> 48 | H22: =COUNTIF(K22:CF22,TRUE)+COUNTIF(K22:CF22,FALSE)-COUNTIF($K$3:CF$3,"Shift 2") -> 49 | I22: =F22- COUNTIFS($K22:CF22,"TRUE",$K$3:CF$3,"Shift 2") -> 30 | J22: =(I22/H22)*100 -> 61.22449 | L22: FALSE | M22: FALSE | N22: TRUE | O22: FALSE | P22: FALSE | Q22: FALSE | R22: TRUE | S22: TRUE | T22: TRUE | U22: FALSE | V22: TRUE | W22: TRUE | X22: FALSE | Y22: TRUE | Z22: TRUE | AA22: FALSE | AB22: TRUE | AC22: TRUE | AD22: FALSE | AE22: TRUE | AF22: TRUE | AG22: FALSE | AH22: TRUE | AI22: FALSE | AJ22: TRUE | AK22: TRUE | AL22: TRUE | AM22: FALSE | AN22: FALSE | AO22: FALSE | AP22: TRUE | AQ22: FALSE | AR22: TRUE | AS22: FALSE | AT22: FALSE | AU22: FALSE | AV22: FALSE | AW22: FALSE | AX22: TRUE | AY22: TRUE | AZ22: FALSE | BA22: TRUE | BB22: FALSE | BC22: FALSE | BD22: TRUE | BE22: TRUE | BF22: FALSE | BG22: TRUE | BH22: TRUE | BI22: TRUE | BJ22: TRUE | BK22: FALSE | BL22: FALSE | BM22: FALSE | BN22: TRUE | BO22: TRUE | BP22: FALSE | BQ22: TRUE | BR22: FALSE | BS22: FALSE | BT22: TRUE | BU22: FALSE | BV22: FALSE | BW22: FALSE | BX22: =COUNTA(AS22:BW22) -> 31 | BY22: =COUNTIF(AS22:BW22,TRUE) -> 13 | BZ22: =BY22/BX22 -> 0.41935484 | CA22: =IF(BZ22>=0.6,"GOOD IN NOV","BAD IN NOV") -> BAD IN NOV | CB22: =COUNTA(AM22:BW22) -> 37 | CC22: =COUNTIF(AM22:BW22,TRUE) -> 15 | CD22: =CC22/CB22 -> 0.40540541 | CE22: =if(CD22>=0.4,"Good in dec","Bad in dec") -> Good in dec | CF22: =IF(AND(CA22="GOOD IN NOV",CE22="Bad in dec"),"CONNECT","NOT CONNECT") -> NOT CONNECT
A23: Rudra Shrotriya | B23: shrotriyarudra@gmail.com | C23: 8305563340 | D23: Indore | E23: =COUNTIF($K23:CF23,TRUE) + COUNTIF($K23:CF23,FALSE) -> 64 | F23: =COUNTIF($K23:CF23,TRUE) -> 36 | G23: =ROUND((F23/E23)*100,0) -> 56 | H23: =COUNTIF(K23:CF23,TRUE)+COUNTIF(K23:CF23,FALSE)-COUNTIF($K$3:CF$3,"Shift 2") -> 49 | I23: =F23- COUNTIFS($K23:CF23,"TRUE",$K$3:CF$3,"Shift 2") -> 34 | J23: =(I23/H23)*100 -> 69.387755 | L23: FALSE | M23: FALSE | N23: FALSE | O23: FALSE | P23: TRUE | Q23: TRUE | R23: TRUE | S23: FALSE | T23: FALSE | U23: FALSE | V23: TRUE | W23: TRUE | X23: FALSE | Y23: TRUE | Z23: TRUE | AA23: FALSE | AB23: TRUE | AC23: FALSE | AD23: FALSE | AE23: FALSE | AF23: TRUE | AG23: FALSE | AH23: TRUE | AI23: FALSE | AJ23: TRUE | AK23: TRUE | AL23: TRUE | AM23: TRUE | AN23: FALSE | AO23: TRUE | AP23: TRUE | AQ23: TRUE | AR23: TRUE | AS23: FALSE | AT23: FALSE | AU23: FALSE | AV23: TRUE | AW23: FALSE | AX23: FALSE | AY23: TRUE | AZ23: FALSE | BA23: TRUE | BB23: TRUE | BC23: FALSE | BD23: FALSE | BE23: TRUE | BF23: FALSE | BG23: TRUE | BH23: TRUE | BI23: TRUE | BJ23: TRUE | BK23: FALSE | BL23: FALSE | BM23: FALSE | BN23: TRUE | BO23: TRUE | BP23: TRUE | BQ23: TRUE | BR23: TRUE | BS23: TRUE | BT23: FALSE | BU23: TRUE | BV23: TRUE | BW23: TRUE | BX23: =COUNTA(AS23:BW23) -> 31 | BY23: =COUNTIF(AS23:BW23,TRUE) -> 18 | BZ23: =BY23/BX23 -> 0.58064516 | CA23: =IF(BZ23>=0.6,"GOOD IN NOV","BAD IN NOV") -> BAD IN NOV | CB23: =COUNTA(AM23:BW23) -> 37 | CC23: =COUNTIF(AM23:BW23,TRUE) -> 23 | CD23: =CC23/CB23 -> 0.62162162 | CE23: =if(CD23>=0.4,"Good in dec","Bad in dec") -> Good in dec | CF23: =IF(AND(CA23="GOOD IN NOV",CE23="Bad in dec"),"CONNECT","NOT CONNECT") -> NOT CONNECT
A24: Sachin Sahu | B24: sachinsahu1036@gmail.com | C24: 7489249341 | D24: Indore | E24: =COUNTIF($K24:CF24,TRUE) + COUNTIF($K24:CF24,FALSE) -> 64 | F24: =COUNTIF($K24:CF24,TRUE) -> 13 | G24: =ROUND((F24/E24)*100,0) -> 20 | H24: =COUNTIF(K24:CF24,TRUE)+COUNTIF(K24:CF24,FALSE)-COUNTIF($K$3:CF$3,"Shift 2") -> 49 | I24: =F24- COUNTIFS($K24:CF24,"TRUE",$K$3:CF$3,"Shift 2") -> 12 | J24: =(I24/H24)*100 -> 24.489796 | L24: FALSE | M24: FALSE | N24: FALSE | O24: FALSE | P24: FALSE | Q24: FALSE | R24: FALSE | S24: FALSE | T24: FALSE | U24: FALSE | V24: FALSE | W24: FALSE | X24: FALSE | Y24: FALSE | Z24: FALSE | AA24: FALSE | AB24: FALSE | AC24: FALSE | AD24: FALSE | AE24: FALSE | AF24: FALSE | AG24: FALSE | AH24: FALSE | AI24: FALSE | AJ24: FALSE | AK24: FALSE | AL24: FALSE | AM24: FALSE | AN24: FALSE | AO24: FALSE | AP24: FALSE | AQ24: FALSE | AR24: FALSE | AS24: FALSE | AT24: FALSE | AU24: FALSE | AV24: FALSE | AW24: FALSE | AX24: FALSE | AY24: FALSE | AZ24: FALSE | BA24: TRUE | BB24: FALSE | BC24: FALSE | BD24: FALSE | BE24: FALSE | BF24: FALSE | BG24: TRUE | BH24: FALSE | BI24: FALSE | BJ24: FALSE | BK24: TRUE | BL24: TRUE | BM24: TRUE | BN24: TRUE | BO24: TRUE | BP24: TRUE | BQ24: TRUE | BR24: TRUE | BS24: TRUE | BT24: TRUE | BU24: TRUE | BV24: FALSE | BW24: FALSE | BX24: =COUNTA(AS24:BW24) -> 31 | BY24: =COUNTIF(AS24:BW24,TRUE) -> 13 | BZ24: =BY24/BX24 -> 0.41935484 | CA24: =IF(BZ24>=0.6,"GOOD IN NOV","BAD IN NOV") -> BAD IN NOV | CB24: =COUNTA(AM24:BW24) -> 37 | CC24: =COUNTIF(AM24:BW24,TRUE) -> 13 | CD24: =CC24/CB24 -> 0.35135135 | CE24: =if(CD24>=0.4,"Good in dec","Bad in dec") -> Bad in dec | CF24: =IF(AND(CA24="GOOD IN NOV",CE24="Bad in dec"),"CONNECT","NOT CONNECT") -> NOT CONNECT
A25: Sanskriti Patil | B25: sanskritigurjar@gmail.com | C25: 8989224411 | D25: Indore | E25: =COUNTIF($K25:CF25,TRUE) + COUNTIF($K25:CF25,FALSE) -> 64 | F25: =COUNTIF($K25:CF25,TRUE) -> 40 | G25: =ROUND((F25/E25)*100,0) -> 63 | H25: =COUNTIF(K25:CF25,TRUE)+COUNTIF(K25:CF25,FALSE)-COUNTIF($K$3:CF$3,"Shift 2") -> 49 | I25: =F25- COUNTIFS($K25:CF25,"TRUE",$K$3:CF$3,"Shift 2") -> 38 | J25: =(I25/H25)*100 -> 77.55102 | L25: FALSE | M25: FALSE | N25: FALSE | O25: FALSE | P25: FALSE | Q25: TRUE | R25: TRUE | S25: FALSE | T25: FALSE | U25: FALSE | V25: TRUE | W25: TRUE | X25: FALSE | Y25: TRUE | Z25: TRUE | AA25: FALSE | AB25: TRUE | AC25: FALSE | AD25: FALSE | AE25: FALSE | AF25: TRUE | AG25: FALSE | AH25: TRUE | AI25: FALSE | AJ25: TRUE | AK25: TRUE | AL25: TRUE | AM25: TRUE | AN25: FALSE | AO25: TRUE | AP25: TRUE | AQ25: FALSE | AR25: TRUE | AS25: FALSE | AT25: FALSE | AU25: FALSE | AV25: TRUE | AW25: FALSE | AX25: TRUE | AY25: TRUE | AZ25: FALSE | BA25: TRUE | BB25: TRUE | BC25: FALSE | BD25: TRUE | BE25: TRUE | BF25: FALSE | BG25: TRUE | BH25: TRUE | BI25: TRUE | BJ25: TRUE | BK25: TRUE | BL25: TRUE | BM25: TRUE | BN25: TRUE | BO25: TRUE | BP25: TRUE | BQ25: TRUE | BR25: TRUE | BS25: TRUE | BT25: TRUE | BU25: TRUE | BV25: TRUE | BW25: TRUE | BX25: =COUNTA(AS25:BW25) -> 31 | BY25: =COUNTIF(AS25:BW25,TRUE) -> 24 | BZ25: =BY25/BX25 -> 0.77419355 | CA25: =IF(BZ25>=0.6,"GOOD IN NOV","BAD IN NOV") -> GOOD IN NOV | CB25: =COUNTA(AM25:BW25) -> 37 | CC25: =COUNTIF(AM25:BW25,TRUE) -> 28 | CD25: =CC25/CB25 -> 0.75675676 | CE25: =if(CD25>=0.4,"Good in dec","Bad in dec") -> Good in dec | CF25: =IF(AND(CA25="GOOD IN NOV",CE25="Bad in dec"),"CONNECT","NOT CONNECT") -> NOT CONNECT
A26: Shivam Shelke | B26: shivamshelke254@gmail.com | C26: 7724026334 | D26: Indore | E26: =COUNTIF($K26:CF26,TRUE) + COUNTIF($K26:CF26,FALSE) -> 64 | F26: =COUNTIF($K26:CF26,TRUE) -> 49 | G26: =ROUND((F26/E26)*100,0) -> 77 | H26: =COUNTIF(K26:CF26,TRUE)+COUNTIF(K26:CF26,FALSE)-COUNTIF($K$3:CF$3,"Shift 2") -> 49 | I26: =F26- COUNTIFS($K26:CF26,"TRUE",$K$3:CF$3,"Shift 2") -> 41 | J26: =(I26/H26)*100 -> 83.673469 | L26: TRUE | M26: TRUE | N26: FALSE | O26: TRUE | P26: TRUE | Q26: TRUE | R26: TRUE | S26: TRUE | T26: TRUE | U26: FALSE | V26: TRUE | W26: TRUE | X26: FALSE | Y26: TRUE | Z26: TRUE | AA26: TRUE | AB26: TRUE | AC26: TRUE | AD26: FALSE | AE26: TRUE | AF26: FALSE | AG26: TRUE | AH26: TRUE | AI26: FALSE | AJ26: TRUE | AK26: TRUE | AL26: TRUE | AM26: FALSE | AN26: FALSE | AO26: TRUE | AP26: TRUE | AQ26: TRUE | AR26: TRUE | AS26: TRUE | AT26: TRUE | AU26: TRUE | AV26: TRUE | AW26: TRUE | AX26: TRUE | AY26: TRUE | AZ26: TRUE | BA26: TRUE | BB26: TRUE | BC26: TRUE | BD26: TRUE | BE26: TRUE | BF26: FALSE | BG26: TRUE | BH26: TRUE | BI26: FALSE | BJ26: FALSE | BK26: TRUE | BL26: TRUE | BM26: TRUE | BN26: TRUE | BO26: TRUE | BP26: TRUE | BQ26: TRUE | BR26: TRUE | BS26: TRUE | BT26: FALSE | BU26: FALSE | BV26: FALSE | BW26: FALSE | BX26: =COUNTA(AS26:BW26) -> 31 | BY26: =COUNTIF(AS26:BW26,TRUE) -> 24 | BZ26: =BY26/BX26 -> 0.77419355 | CA26: =IF(BZ26>=0.6,"GOOD IN NOV","BAD IN NOV") -> GOOD IN NOV | CB26: =COUNTA(AM26:BW26) -> 37 | CC26: =COUNTIF(AM26:BW26,TRUE) -> 28 | CD26: =CC26/CB26 -> 0.75675676 | CE26: =if(CD26>=0.4,"Good in dec","Bad in dec") -> Good in dec | CF26: =IF(AND(CA26="GOOD IN NOV",CE26="Bad in dec"),"CONNECT","NOT CONNECT") -> NOT CONNECT
A27: Shivam Tripathi | B27: Stripathi4876@gmail.com | C27: 6261208093 | D27: Indore | E27: =COUNTIF($K27:CF27,TRUE) + COUNTIF($K27:CF27,FALSE) -> 64 | F27: =COUNTIF($K27:CF27,TRUE) -> 32 | G27: =ROUND((F27/E27)*100,0) -> 50 | H27: =COUNTIF(K27:CF27,TRUE)+COUNTIF(K27:CF27,FALSE)-COUNTIF($K$3:CF$3,"Shift 2") -> 49 | I27: =F27- COUNTIFS($K27:CF27,"TRUE",$K$3:CF$3,"Shift 2") -> 30 | J27: =(I27/H27)*100 -> 61.22449 | L27: TRUE | M27: FALSE | N27: TRUE | O27: FALSE | P27: TRUE | Q27: FALSE | R27: TRUE | S27: FALSE | T27: FALSE | U27: FALSE | V27: FALSE | W27: FALSE | X27: FALSE | Y27: FALSE | Z27: TRUE | AA27: FALSE | AB27: FALSE | AC27: FALSE | AD27: FALSE | AE27: FALSE | AF27: TRUE | AG27: FALSE | AH27: TRUE | AI27: FALSE | AJ27: TRUE | AK27: TRUE | AL27: TRUE | AM27: TRUE | AN27: FALSE | AO27: TRUE | AP27: TRUE | AQ27: FALSE | AR27: TRUE | AS27: TRUE | AT27: FALSE | AU27: TRUE | AV27: TRUE | AW27: TRUE | AX27: TRUE | AY27: TRUE | AZ27: FALSE | BA27: TRUE | BB27: TRUE | BC27: FALSE | BD27: FALSE | BE27: FALSE | BF27: FALSE | BG27: FALSE | BH27: FALSE | BI27: FALSE | BJ27: TRUE | BK27: TRUE | BL27: TRUE | BM27: TRUE | BN27: TRUE | BO27: TRUE | BP27: TRUE | BQ27: TRUE | BR27: TRUE | BS27: TRUE | BT27: FALSE | BU27: FALSE | BV27: FALSE | BW27: FALSE | BX27: =COUNTA(AS27:BW27) -> 31 | BY27: =COUNTIF(AS27:BW27,TRUE) -> 18 | BZ27: =BY27/BX27 -> 0.58064516 | CA27: =IF(BZ27>=0.6,"GOOD IN NOV","BAD IN NOV") -> BAD IN NOV | CB27: =COUNTA(AM27:BW27) -> 37 | CC27: =COUNTIF(AM27:BW27,TRUE) -> 22 | CD27: =CC27/CB27 -> 0.59459459 | CE27: =if(CD27>=0.4,"Good in dec","Bad in dec") -> Good in dec | CF27: =IF(AND(CA27="GOOD IN NOV",CE27="Bad in dec"),"CONNECT","NOT CONNECT") -> NOT CONNECT
A28: Shivangi Singh | B28: shivangisingh05052005@gmail.com | C28: 8602245009 | D28: Indore | E28: =COUNTIF($K28:CF28,TRUE) + COUNTIF($K28:CF28,FALSE) -> 64 | F28: =COUNTIF($K28:CF28,TRUE) -> 29 | G28: =ROUND((F28/E28)*100,0) -> 45 | H28: =COUNTIF(K28:CF28,TRUE)+COUNTIF(K28:CF28,FALSE)-COUNTIF($K$3:CF$3,"Shift 2") -> 49 | I28: =F28- COUNTIFS($K28:CF28,"TRUE",$K$3:CF$3,"Shift 2") -> 26 | J28: =(I28/H28)*100 -> 53.061224 | L28: FALSE | M28: FALSE | N28: FALSE | O28: FALSE | P28: FALSE | Q28: FALSE | R28: FALSE | S28: FALSE | T28: FALSE | U28: FALSE | V28: TRUE | W28: TRUE | X28: FALSE | Y28: TRUE | Z28: TRUE | AA28: FALSE | AB28: TRUE | AC28: TRUE | AD28: FALSE | AE28: TRUE | AF28: TRUE | AG28: FALSE | AH28: TRUE | AI28: FALSE | AJ28: TRUE | AK28: TRUE | AL28: TRUE | AM28: TRUE | AN28: FALSE | AO28: TRUE | AP28: TRUE | AQ28: TRUE | AR28: TRUE | AS28: TRUE | AT28: FALSE | AU28: TRUE | AV28: TRUE | AW28: TRUE | AX28: TRUE | AY28: TRUE | AZ28: FALSE | BA28: TRUE | BB28: TRUE | BC28: TRUE | BD28: TRUE | BE28: TRUE | BF28: FALSE | BG28: TRUE | BH28: FALSE | BI28: FALSE | BJ28: FALSE | BK28: FALSE | BL28: FALSE | BM28: FALSE | BN28: FALSE | BO28: FALSE | BP28: FALSE | BQ28: FALSE | BR28: FALSE | BS28: FALSE | BT28: FALSE | BU28: FALSE | BV28: FALSE | BW28: FALSE | BX28: =COUNTA(AS28:BW28) -> 31 | BY28: =COUNTIF(AS28:BW28,TRUE) -> 12 | BZ28: =BY28/BX28 -> 0.38709677 | CA28: =IF(BZ28>=0.6,"GOOD IN NOV","BAD IN NOV") -> BAD IN NOV | CB28: =COUNTA(AM28:BW28) -> 37 | CC28: =COUNTIF(AM28:BW28,TRUE) -> 17 | CD28: =CC28/CB28 -> 0.45945946 | CE28: =if(CD28>=0.4,"Good in dec","Bad in dec") -> Good in dec | CF28: =IF(AND(CA28="GOOD IN NOV",CE28="Bad in dec"),"CONNECT","NOT CONNECT") -> NOT CONNECT
A29: Shubham Singh Chouhan | B29: shubhamschauhan31@gmail.com | C29: 9754884661 | D29: Indore | E29: =COUNTIF($K29:CF29,TRUE) + COUNTIF($K29:CF29,FALSE) -> 64 | F29: =COUNTIF($K29:CF29,TRUE) -> 50 | G29: =ROUND((F29/E29)*100,0) -> 78 | H29: =COUNTIF(K29:CF29,TRUE)+COUNTIF(K29:CF29,FALSE)-COUNTIF($K$3:CF$3,"Shift 2") -> 49 | I29: =F29- COUNTIFS($K29:CF29,"TRUE",$K$3:CF$3,"Shift 2") -> 44 | J29: =(I29/H29)*100 -> 89.795918 | L29: TRUE | M29: TRUE | N29: TRUE | O29: TRUE | P29: FALSE | Q29: TRUE | R29: TRUE | S29: TRUE | T29: TRUE | U29: TRUE | V29: TRUE | W29: TRUE | X29: FALSE | Y29: TRUE | Z29: TRUE | AA29: TRUE | AB29: TRUE | AC29: TRUE | AD29: FALSE | AE29: TRUE | AF29: TRUE | AG29: FALSE | AH29: TRUE | AI29: TRUE | AJ29: TRUE | AK29: TRUE | AL29: TRUE | AM29: TRUE | AN29: FALSE | AO29: TRUE | AP29: TRUE | AQ29: FALSE | AR29: TRUE | AS29: TRUE | AT29: FALSE | AU29: FALSE | AV29: TRUE | AW29: TRUE | AX29: TRUE | AY29: TRUE | AZ29: TRUE | BA29: TRUE | BB29: FALSE | BC29: FALSE | BD29: FALSE | BE29: FALSE | BF29: FALSE | BG29: TRUE | BH29: TRUE | BI29: FALSE | BJ29: TRUE | BK29: TRUE | BL29: TRUE | BM29: TRUE | BN29: TRUE | BO29: TRUE | BP29: TRUE | BQ29: TRUE | BR29: TRUE | BS29: TRUE | BT29: TRUE | BU29: TRUE | BV29: TRUE | BW29: TRUE | BX29: =COUNTA(AS29:BW29) -> 31 | BY29: =COUNTIF(AS29:BW29,TRUE) -> 23 | BZ29: =BY29/BX29 -> 0.74193548 | CA29: =IF(BZ29>=0.6,"GOOD IN NOV","BAD IN NOV") -> GOOD IN NOV | CB29: =COUNTA(AM29:BW29) -> 37 | CC29: =COUNTIF(AM29:BW29,TRUE) -> 27 | CD29: =CC29/CB29 -> 0.72972973 | CE29: =if(CD29>=0.4,"Good in dec","Bad in dec") -> Good in dec | CF29: =IF(AND(CA29="GOOD IN NOV",CE29="Bad in dec"),"CONNECT","NOT CONNECT") -> NOT CONNECT
A30: Shubhangi Tiwari | B30: shubhangitiwari4113@gmail.com | C30: 9993724306 | D30: Indore | E30: =COUNTIF($K30:CF30,TRUE) + COUNTIF($K30:CF30,FALSE) -> 64 | F30: =COUNTIF($K30:CF30,TRUE) -> 14 | G30: =ROUND((F30/E30)*100,0) -> 22 | H30: =COUNTIF(K30:CF30,TRUE)+COUNTIF(K30:CF30,FALSE)-COUNTIF($K$3:CF$3,"Shift 2") -> 49 | I30: =F30- COUNTIFS($K30:CF30,"TRUE",$K$3:CF$3,"Shift 2") -> 14 | J30: =(I30/H30)*100 -> 28.571429 | L30: FALSE | M30: FALSE | N30: FALSE | O30: FALSE | P30: FALSE | Q30: FALSE | R30: FALSE | S30: FALSE | T30: FALSE | U30: FALSE | V30: FALSE | W30: FALSE | X30: FALSE | Y30: FALSE | Z30: FALSE | AA30: FALSE | AB30: FALSE | AC30: FALSE | AD30: FALSE | AE30: TRUE | AF30: FALSE | AG30: FALSE | AH30: FALSE | AI30: FALSE | AJ30: FALSE | AK30: TRUE | AL30: TRUE | AM30: TRUE | AN30: FALSE | AO30: TRUE | AP30: FALSE | AQ30: FALSE | AR30: TRUE | AS30: FALSE | AT30: FALSE | AU30: FALSE | AV30: FALSE | AW30: FALSE | AX30: FALSE | AY30: FALSE | AZ30: FALSE | BA30: FALSE | BB30: FALSE | BC30: FALSE | BD30: FALSE | BE30: FALSE | BF30: FALSE | BG30: FALSE | BH30: FALSE | BI30: FALSE | BJ30: FALSE | BK30: FALSE | BL30: FALSE | BM30: FALSE | BN30: TRUE | BO30: TRUE | BP30: TRUE | BQ30: TRUE | BR30: TRUE | BS30: TRUE | BT30: TRUE | BU30: TRUE | BV30: FALSE | BW30: FALSE | BX30: =COUNTA(AS30:BW30) -> 31 | BY30: =COUNTIF(AS30:BW30,TRUE) -> 8 | BZ30: =BY30/BX30 -> 0.25806452 | CA30: =IF(BZ30>=0.6,"GOOD IN NOV","BAD IN NOV") -> BAD IN NOV | CB30: =COUNTA(AM30:BW30) -> 37 | CC30: =COUNTIF(AM30:BW30,TRUE) -> 11 | CD30: =CC30/CB30 -> 0.2972973 | CE30: =if(CD30>=0.4,"Good in dec","Bad in dec") -> Bad in dec | CF30: =IF(AND(CA30="GOOD IN NOV",CE30="Bad in dec"),"CONNECT","NOT CONNECT") -> NOT CONNECT
... A40: Abhishek singh | B40: singhabhishek76785@gmail.com | C40: 6306239288 | D40: Lucknow | E40: =COUNTIF($K40:CF40,TRUE) + COUNTIF($K40:CF40,FALSE) -> 64 | F40: =COUNTIF($K40:CF40,TRUE) -> 46 | G40: =ROUND((F40/E40)*100,0) -> 72 | H40: =COUNTIF(K40:CF40,TRUE)+COUNTIF(K40:CF40,FALSE)-COUNTIF($K$3:CF$3,"Shift 2") -> 49 | I40: =F40- COUNTIFS($K40:CF40,"TRUE",$K$3:CF$3,"Shift 2") -> 39 | J40: =(I40/H40)*100 -> 79.591837 | L40: TRUE | M40: TRUE | N40: TRUE | O40: TRUE | P40: FALSE | Q40: FALSE | R40: TRUE | S40: FALSE | T40: FALSE | U40: FALSE | V40: TRUE | W40: TRUE | X40: FALSE | Y40: FALSE | Z40: TRUE | AA40: TRUE | AB40: TRUE | AC40: TRUE | AD40: TRUE | AE40: TRUE | AF40: TRUE | AG40: FALSE | AH40: TRUE | AI40: FALSE | AJ40: TRUE | AK40: TRUE | AL40: FALSE | AM40: TRUE | AN40: FALSE | AO40: FALSE | AP40: TRUE | AQ40: FALSE | AR40: FALSE | AS40: FALSE | AT40: TRUE | AU40: TRUE | AV40: TRUE | AW40: FALSE | AX40: TRUE | AY40: TRUE | AZ40: TRUE | BA40: TRUE | BB40: TRUE | BC40: TRUE | BD40: TRUE | BE40: TRUE | BF40: FALSE | BG40: TRUE | BH40: FALSE | BI40: TRUE | BJ40: TRUE | BK40: TRUE | BL40: TRUE | BM40: TRUE | BN40: TRUE | BO40: TRUE | BP40: TRUE | BQ40: TRUE | BR40: TRUE | BS40: TRUE | BT40: TRUE | BU40: TRUE | BV40: TRUE | BW40: TRUE | BX40: =COUNTA(AS40:BW40) -> 31 | BY40: =COUNTIF(AS40:BW40,TRUE) -> 27 | BZ40: =BY40/BX40 -> 0.87096774 | CA40: =IF(BZ40>=0.6,"GOOD IN NOV","BAD IN NOV") -> GOOD IN NOV | CB40: =COUNTA(AM40:BW40) -> 37 | CC40: =COUNTIF(AM40:BW40,TRUE) -> 29 | CD40: =CC40/CB40 -> 0.78378378 | CE40: =if(CD40>=0.4,"Good in dec","Bad in dec") -> Good in dec | CF40: =IF(AND(CA40="GOOD IN NOV",CE40="Bad in dec"),"CONNECT","NOT CONNECT") -> NOT CONNECT
A41: Ajit Kumar | C41: 8808148079 | D41: Lucknow | E41: =COUNTIF($K41:CF41,TRUE) + COUNTIF($K41:CF41,FALSE) -> 64 | F41: =COUNTIF($K41:CF41,TRUE) -> 2 | G41: =ROUND((F41/E41)*100,0) -> 3 | H41: =COUNTIF(K41:CF41,TRUE)+COUNTIF(K41:CF41,FALSE)-COUNTIF($K$3:CF$3,"Shift 2") -> 49 | I41: =F41- COUNTIFS($K41:CF41,"TRUE",$K$3:CF$3,"Shift 2") -> 2 | J41: =(I41/H41)*100 -> 4.0816327 | L41: FALSE | M41: FALSE | N41: FALSE | O41: FALSE | P41: FALSE | Q41: FALSE | R41: FALSE | S41: FALSE | T41: FALSE | U41: FALSE | V41: FALSE | W41: FALSE | X41: FALSE | Y41: FALSE | Z41: FALSE | AA41: FALSE | AB41: FALSE | AC41: FALSE | AD41: FALSE | AE41: FALSE | AF41: FALSE | AG41: FALSE | AH41: FALSE | AI41: FALSE | AJ41: FALSE | AK41: FALSE | AL41: FALSE | AM41: FALSE | AN41: FALSE | AO41: FALSE | AP41: FALSE | AQ41: FALSE | AR41: FALSE | AS41: FALSE | AT41: FALSE | AU41: FALSE | AV41: FALSE | AW41: FALSE | AX41: FALSE | AY41: FALSE | AZ41: FALSE | BA41: FALSE | BB41: FALSE | BC41: FALSE | BD41: FALSE | BE41: FALSE | BF41: FALSE | BG41: FALSE | BH41: FALSE | BI41: FALSE | BJ41: FALSE | BK41: FALSE | BL41: FALSE | BM41: FALSE | BN41: FALSE | BO41: FALSE | BP41: FALSE | BQ41: FALSE | BR41: TRUE | BS41: TRUE | BT41: FALSE | BU41: FALSE | BV41: FALSE | BW41: FALSE | BX41: =COUNTA(AS41:BW41) -> 31 | BY41: =COUNTIF(AS41:BW41,TRUE) -> 2 | BZ41: =BY41/BX41 -> 0.064516129 | CA41: =IF(BZ41>=0.6,"GOOD IN NOV","BAD IN NOV") -> BAD IN NOV | CB41: =COUNTA(AM41:BW41) -> 37 | CC41: =COUNTIF(AM41:BW41,TRUE) -> 2 | CD41: =CC41/CB41 -> 0.054054054 | CE41: =if(CD41>=0.4,"Good in dec","Bad in dec") -> Bad in dec | CF41: =IF(AND(CA41="GOOD IN NOV",CE41="Bad in dec"),"CONNECT","NOT CONNECT") -> NOT CONNECT
A42: Akansksha Pal | B42: adarshpal567643@gmail.com | C42: 9076651533 | D42: Lucknow | E42: =COUNTIF($K42:CF42,TRUE) + COUNTIF($K42:CF42,FALSE) -> 64 | F42: =COUNTIF($K42:CF42,TRUE) -> 54 | G42: =ROUND((F42/E42)*100,0) -> 84 | H42: =COUNTIF(K42:CF42,TRUE)+COUNTIF(K42:CF42,FALSE)-COUNTIF($K$3:CF$3,"Shift 2") -> 49 | I42: =F42- COUNTIFS($K42:CF42,"TRUE",$K$3:CF$3,"Shift 2") -> 42 | J42: =(I42/H42)*100 -> 85.714286 | L42: TRUE | M42: TRUE | N42: TRUE | O42: FALSE | P42: TRUE | Q42: TRUE | R42: TRUE | S42: TRUE | T42: TRUE | U42: TRUE | V42: TRUE | W42: FALSE | X42: FALSE | Y42: FALSE | Z42: TRUE | AA42: TRUE | AB42: TRUE | AC42: TRUE | AD42: TRUE | AE42: TRUE | AF42: TRUE | AG42: TRUE | AH42: TRUE | AI42: TRUE | AJ42: TRUE | AK42: TRUE | AL42: FALSE | AM42: TRUE | AN42: FALSE | AO42: TRUE | AP42: TRUE | AQ42: TRUE | AR42: TRUE | AS42: TRUE | AT42: TRUE | AU42: TRUE | AV42: TRUE | AW42: FALSE | AX42: FALSE | AY42: TRUE | AZ42: TRUE | BA42: TRUE | BB42: TRUE | BC42: TRUE | BD42: TRUE | BE42: TRUE | BF42: TRUE | BG42: TRUE | BH42: TRUE | BI42: TRUE | BJ42: TRUE | BK42: TRUE | BL42: TRUE | BM42: TRUE | BN42: TRUE | BO42: TRUE | BP42: TRUE | BQ42: TRUE | BR42: FALSE | BS42: TRUE | BT42: FALSE | BU42: TRUE | BV42: TRUE | BW42: TRUE | BX42: =COUNTA(AS42:BW42) -> 31 | BY42: =COUNTIF(AS42:BW42,TRUE) -> 27 | BZ42: =BY42/BX42 -> 0.87096774 | CA42: =IF(BZ42>=0.6,"GOOD IN NOV","BAD IN NOV") -> GOOD IN NOV | CB42: =COUNTA(AM42:BW42) -> 37 | CC42: =COUNTIF(AM42:BW42,TRUE) -> 32 | CD42: =CC42/CB42 -> 0.86486486 | CE42: =if(CD42>=0.4,"Good in dec","Bad in dec") -> Good in dec | CF42: =IF(AND(CA42="GOOD IN NOV",CE42="Bad in dec"),"CONNECT","NOT CONNECT") -> NOT CONNECT
A43: Akash Gautam | B43: gautam91700@gmail.com | C43: 9170076346 | D43: Lucknow | E43: =COUNTIF($K43:CF43,TRUE) + COUNTIF($K43:CF43,FALSE) -> 64 | F43: =COUNTIF($K43:CF43,TRUE) -> 59 | G43: =ROUND((F43/E43)*100,0) -> 92 | H43: =COUNTIF(K43:CF43,TRUE)+COUNTIF(K43:CF43,FALSE)-COUNTIF($K$3:CF$3,"Shift 2") -> 49 | I43: =F43- COUNTIFS($K43:CF43,"TRUE",$K$3:CF$3,"Shift 2") -> 48 | J43: =(I43/H43)*100 -> 97.959184 | L43: TRUE | M43: TRUE | N43: TRUE | O43: TRUE | P43: TRUE | Q43: TRUE | R43: FALSE | S43: TRUE | T43: TRUE | U43: FALSE | V43: TRUE | W43: TRUE | X43: FALSE | Y43: TRUE | Z43: TRUE | AA43: TRUE | AB43: TRUE | AC43: TRUE | AD43: TRUE | AE43: TRUE | AF43: TRUE | AG43: TRUE | AH43: TRUE | AI43: TRUE | AJ43: TRUE | AK43: TRUE | AL43: TRUE | AM43: TRUE | AN43: FALSE | AO43: TRUE | AP43: TRUE | AQ43: TRUE | AR43: TRUE | AS43: TRUE | AT43: TRUE | AU43: TRUE | AV43: TRUE | AW43: TRUE | AX43: TRUE | AY43: TRUE | AZ43: TRUE | BA43: TRUE | BB43: TRUE | BC43: FALSE | BD43: TRUE | BE43: TRUE | BF43: TRUE | BG43: TRUE | BH43: TRUE | BI43: TRUE | BJ43: TRUE | BK43: TRUE | BL43: TRUE | BM43: TRUE | BN43: TRUE | BO43: TRUE | BP43: TRUE | BQ43: TRUE | BR43: TRUE | BS43: TRUE | BT43: TRUE | BU43: TRUE | BV43: TRUE | BW43: TRUE | BX43: =COUNTA(AS43:BW43) -> 31 | BY43: =COUNTIF(AS43:BW43,TRUE) -> 30 | BZ43: =BY43/BX43 -> 0.96774194 | CA43: =IF(BZ43>=0.6,"GOOD IN NOV","BAD IN NOV") -> GOOD IN NOV | CB43: =COUNTA(AM43:BW43) -> 37 | CC43: =COUNTIF(AM43:BW43,TRUE) -> 35 | CD43: =CC43/CB43 -> 0.94594595 | CE43: =if(CD43>=0.4,"Good in dec","Bad in dec") -> Good in dec | CF43: =IF(AND(CA43="GOOD IN NOV",CE43="Bad in dec"),"CONNECT","NOT CONNECT") -> NOT CONNECT
A44: Ambuj Singh | B44: ambujsiingh1103@gmail.com | C44: 8090021601 | D44: Lucknow | E44: =COUNTIF($K44:CF44,TRUE) + COUNTIF($K44:CF44,FALSE) -> 64 | F44: =COUNTIF($K44:CF44,TRUE) -> 32 | G44: =ROUND((F44/E44)*100,0) -> 50 | H44: =COUNTIF(K44:CF44,TRUE)+COUNTIF(K44:CF44,FALSE)-COUNTIF($K$3:CF$3,"Shift 2") -> 49 | I44: =F44- COUNTIFS($K44:CF44,"TRUE",$K$3:CF$3,"Shift 2") -> 25 | J44: =(I44/H44)*100 -> 51.020408 | L44: FALSE | M44: TRUE | N44: TRUE | O44: FALSE | P44: FALSE | Q44: FALSE | R44: FALSE | S44: TRUE | T44: FALSE | U44: FALSE | V44: FALSE | W44: FALSE | X44: FALSE | Y44: FALSE | Z44: TRUE | AA44: TRUE | AB44: TRUE | AC44: FALSE | AD44: TRUE | AE44: TRUE | AF44: TRUE | AG44: FALSE | AH44: TRUE | AI44: TRUE | AJ44: TRUE | AK44: FALSE | AL44: TRUE | AM44: FALSE | AN44: FALSE | AO44: FALSE | AP44: FALSE | AQ44: FALSE | AR44: TRUE | AS44: TRUE | AT44: TRUE | AU44: TRUE | AV44: FALSE | AW44: FALSE | AX44: FALSE | AY44: TRUE | AZ44: FALSE | BA44: FALSE | BB44: TRUE | BC44: FALSE | BD44: TRUE | BE44: TRUE | BF44: TRUE | BG44: TRUE | BH44: TRUE | BI44: TRUE | BJ44: TRUE | BK44: TRUE | BL44: TRUE | BM44: TRUE | BN44: FALSE | BO44: FALSE | BP44: TRUE | BQ44: TRUE | BR44: FALSE | BS44: FALSE | BT44: TRUE | BU44: FALSE | BV44: FALSE | BW44: FALSE | BX44: =COUNTA(AS44:BW44) -> 31 | BY44: =COUNTIF(AS44:BW44,TRUE) -> 18 | BZ44: =BY44/BX44 -> 0.58064516 | CA44: =IF(BZ44>=0.6,"GOOD IN NOV","BAD IN NOV") -> BAD IN NOV | CB44: =COUNTA(AM44:BW44) -> 37 | CC44: =COUNTIF(AM44:BW44,TRUE) -> 19 | CD44: =CC44/CB44 -> 0.51351351 | CE44: =if(CD44>=0.4,"Good in dec","Bad in dec") -> Good in dec | CF44: =IF(AND(CA44="GOOD IN NOV",CE44="Bad in dec"),"CONNECT","NOT CONNECT") -> NOT CONNECT
A45: Anchal singh | B45: anchals6392@gmail.com | C45: 6392155047 | D45: Lucknow | E45: =COUNTIF($K45:CF45,TRUE) + COUNTIF($K45:CF45,FALSE) -> 64 | F45: =COUNTIF($K45:CF45,TRUE) -> 50 | G45: =ROUND((F45/E45)*100,0) -> 78 | H45: =COUNTIF(K45:CF45,TRUE)+COUNTIF(K45:CF45,FALSE)-COUNTIF($K$3:CF$3,"Shift 2") -> 49 | I45: =F45- COUNTIFS($K45:CF45,"TRUE",$K$3:CF$3,"Shift 2") -> 41 | J45: =(I45/H45)*100 -> 83.673469 | L45: TRUE | M45: TRUE | N45: FALSE | O45: FALSE | P45: TRUE | Q45: TRUE | R45: TRUE | S45: TRUE | T45: TRUE | U45: TRUE | V45: TRUE | W45: TRUE | X45: FALSE | Y45: TRUE | Z45: TRUE | AA45: TRUE | AB45: TRUE | AC45: TRUE | AD45: TRUE | AE45: TRUE | AF45: TRUE | AG45: TRUE | AH45: TRUE | AI45: FALSE | AJ45: TRUE | AK45: TRUE | AL45: TRUE | AM45: TRUE | AN45: FALSE | AO45: TRUE | AP45: TRUE | AQ45: TRUE | AR45: TRUE | AS45: TRUE | AT45: TRUE | AU45: TRUE | AV45: TRUE | AW45: FALSE | AX45: FALSE | AY45: TRUE | AZ45: TRUE | BA45: TRUE | BB45: TRUE | BC45: FALSE | BD45: TRUE | BE45: FALSE | BF45: FALSE | BG45: FALSE | BH45: TRUE | BI45: TRUE | BJ45: TRUE | BK45: TRUE | BL45: TRUE | BM45: TRUE | BN45: TRUE | BO45: TRUE | BP45: FALSE | BQ45: TRUE | BR45: TRUE | BS45: TRUE | BT45: TRUE | BU45: TRUE | BV45: FALSE | BW45: FALSE | BX45: =COUNTA(AS45:BW45) -> 31 | BY45: =COUNTIF(AS45:BW45,TRUE) -> 22 | BZ45: =BY45/BX45 -> 0.70967742 | CA45: =IF(BZ45>=0.6,"GOOD IN NOV","BAD IN NOV") -> GOOD IN NOV | CB45: =COUNTA(AM45:BW45) -> 37 | CC45: =COUNTIF(AM45:BW45,TRUE) -> 27 | CD45: =CC45/CB45 -> 0.72972973 | CE45: =if(CD45>=0.4,"Good in dec","Bad in dec") -> Good in dec | CF45: =IF(AND(CA45="GOOD IN NOV",CE45="Bad in dec"),"CONNECT","NOT CONNECT") -> NOT CONNECT
A46: AnjaliYadav | B46: yadavanjali2901@gmail.com | C46: 8758980437 | D46: Lucknow | E46: =COUNTIF($K46:CF46,TRUE) + COUNTIF($K46:CF46,FALSE) -> 64 | F46: =COUNTIF($K46:CF46,TRUE) -> 36 | G46: =ROUND((F46/E46)*100,0) -> 56 | H46: =COUNTIF(K46:CF46,TRUE)+COUNTIF(K46:CF46,FALSE)-COUNTIF($K$3:CF$3,"Shift 2") -> 49 | I46: =F46- COUNTIFS($K46:CF46,"TRUE",$K$3:CF$3,"Shift 2") -> 31 | J46: =(I46/H46)*100 -> 63.265306 | L46: TRUE | M46: FALSE | N46: FALSE | O46: FALSE | P46: TRUE | Q46: FALSE | R46: FALSE | S46: FALSE | T46: TRUE | U46: TRUE | V46: TRUE | W46: TRUE | X46: FALSE | Y46: TRUE | Z46: TRUE | AA46: FALSE | AB46: FALSE | AC46: FALSE | AD46: FALSE | AE46: FALSE | AF46: FALSE | AG46: FALSE | AH46: FALSE | AI46: FALSE | AJ46: FALSE | AK46: FALSE | AL46: TRUE | AM46: TRUE | AN46: FALSE | AO46: TRUE | AP46: TRUE | AQ46: TRUE | AR46: TRUE | AS46: TRUE | AT46: FALSE | AU46: FALSE | AV46: TRUE | AW46: FALSE | AX46: FALSE | AY46: TRUE | AZ46: FALSE | BA46: FALSE | BB46: TRUE | BC46: FALSE | BD46: TRUE | BE46: TRUE | BF46: TRUE | BG46: TRUE | BH46: TRUE | BI46: TRUE | BJ46: TRUE | BK46: TRUE | BL46: TRUE | BM46: TRUE | BN46: FALSE | BO46: FALSE | BP46: TRUE | BQ46: TRUE | BR46: TRUE | BS46: TRUE | BT46: TRUE | BU46: TRUE | BV46: TRUE | BW46: TRUE | BX46: =COUNTA(AS46:BW46) -> 31 | BY46: =COUNTIF(AS46:BW46,TRUE) -> 22 | BZ46: =BY46/BX46 -> 0.70967742 | CA46: =IF(BZ46>=0.6,"GOOD IN NOV","BAD IN NOV") -> GOOD IN NOV | CB46: =COUNTA(AM46:BW46) -> 37 | CC46: =COUNTIF(AM46:BW46,TRUE) -> 27 | CD46: =CC46/CB46 -> 0.72972973 | CE46: =if(CD46>=0.4,"Good in dec","Bad in dec") -> Good in dec | CF46: =IF(AND(CA46="GOOD IN NOV",CE46="Bad in dec"),"CONNECT","NOT CONNECT") -> NOT CONNECT
A47: Anshul Yadav | B47: anshulanshyadav00@gmail.com | C47: 9140706364 | D47: Lucknow | E47: =COUNTIF($K47:CF47,TRUE) + COUNTIF($K47:CF47,FALSE) -> 64 | F47: =COUNTIF($K47:CF47,TRUE) -> 18 | G47: =ROUND((F47/E47)*100,0) -> 28 | H47: =COUNTIF(K47:CF47,TRUE)+COUNTIF(K47:CF47,FALSE)-COUNTIF($K$3:CF$3,"Shift 2") -> 49 | I47: =F47- COUNTIFS($K47:CF47,"TRUE",$K$3:CF$3,"Shift 2") -> 16 | J47: =(I47/H47)*100 -> 32.653061 | L47: FALSE | M47: TRUE | N47: FALSE | O47: FALSE | P47: FALSE | Q47: FALSE | R47: FALSE | S47: FALSE | T47: FALSE | U47: FALSE | V47: FALSE | W47: FALSE | X47: FALSE | Y47: FALSE | Z47: FALSE | AA47: FALSE | AB47: FALSE | AC47: FALSE | AD47: FALSE | AE47: FALSE | AF47: FALSE | AG47: FALSE | AH47: TRUE | AI47: FALSE | AJ47: FALSE | AK47: FALSE | AL47: TRUE | AM47: FALSE | AN47: FALSE | AO47: FALSE | AP47: FALSE | AQ47: FALSE | AR47: FALSE | AS47: FALSE | AT47: FALSE | AU47: FALSE | AV47: FALSE | AW47: FALSE | AX47: FALSE | AY47: TRUE | AZ47: FALSE | BA47: FALSE | BB47: FALSE | BC47: FALSE | BD47: FALSE | BE47: TRUE | BF47: FALSE | BG47: FALSE | BH47: TRUE | BI47: TRUE | BJ47: TRUE | BK47: TRUE | BL47: TRUE | BM47: TRUE | BN47: TRUE | BO47: TRUE | BP47: FALSE | BQ47: FALSE | BR47: TRUE | BS47: TRUE | BT47: FALSE | BU47: TRUE | BV47: TRUE | BW47: TRUE | BX47: =COUNTA(AS47:BW47) -> 31 | BY47: =COUNTIF(AS47:BW47,TRUE) -> 15 | BZ47: =BY47/BX47 -> 0.48387097 | CA47: =IF(BZ47>=0.6,"GOOD IN NOV","BAD IN NOV") -> BAD IN NOV | CB47: =COUNTA(AM47:BW47) -> 37 | CC47: =COUNTIF(AM47:BW47,TRUE) -> 15 | CD47: =CC47/CB47 -> 0.40540541 | CE47: =if(CD47>=0.4,"Good in dec","Bad in dec") -> Good in dec | CF47: =IF(AND(CA47="GOOD IN NOV",CE47="Bad in dec"),"CONNECT","NOT CONNECT") -> NOT CONNECT
A48: Aryan Dwivedi | B48: aryandwive769@gmail.com | C48: 8707515961 | D48: Lucknow | E48: =COUNTIF($K48:CF48,TRUE) + COUNTIF($K48:CF48,FALSE) -> 64 | F48: =COUNTIF($K48:CF48,TRUE) -> 42 | G48: =ROUND((F48/E48)*100,0) -> 66 | H48: =COUNTIF(K48:CF48,TRUE)+COUNTIF(K48:CF48,FALSE)-COUNTIF($K$3:CF$3,"Shift 2") -> 49 | I48: =F48- COUNTIFS($K48:CF48,"TRUE",$K$3:CF$3,"Shift 2") -> 36 | J48: =(I48/H48)*100 -> 73.469388 | L48: TRUE | M48: TRUE | N48: TRUE | O48: TRUE | P48: FALSE | Q48: FALSE | R48: FALSE | S48: TRUE | T48: TRUE | U48: FALSE | V48: TRUE | W48: TRUE | X48: FALSE | Y48: TRUE | Z48: TRUE | AA48: TRUE | AB48: TRUE | AC48: TRUE | AD48: TRUE | AE48: TRUE | AF48: FALSE | AG48: FALSE | AH48: FALSE | AI48: TRUE | AJ48: TRUE | AK48: TRUE | AL48: TRUE | AM48: TRUE | AN48: FALSE | AO48: TRUE | AP48: TRUE | AQ48: TRUE | AR48: TRUE | AS48: FALSE | AT48: FALSE | AU48: TRUE | AV48: TRUE | AW48: FALSE | AX48: TRUE | AY48: TRUE | AZ48: TRUE | BA48: TRUE | BB48: TRUE | BC48: TRUE | BD48: TRUE | BE48: TRUE | BF48: FALSE | BG48: TRUE | BH48: FALSE | BI48: FALSE | BJ48: FALSE | BK48: FALSE | BL48: FALSE | BM48: FALSE | BN48: FALSE | BO48: FALSE | BP48: TRUE | BQ48: FALSE | BR48: TRUE | BS48: TRUE | BT48: TRUE | BU48: TRUE | BV48: TRUE | BW48: TRUE | BX48: =COUNTA(AS48:BW48) -> 31 | BY48: =COUNTIF(AS48:BW48,TRUE) -> 18 | BZ48: =BY48/BX48 -> 0.58064516 | CA48: =IF(BZ48>=0.6,"GOOD IN NOV","BAD IN NOV") -> BAD IN NOV | CB48: =COUNTA(AM48:BW48) -> 37 | CC48: =COUNTIF(AM48:BW48,TRUE) -> 23 | CD48: =CC48/CB48 -> 0.62162162 | CE48: =if(CD48>=0.4,"Good in dec","Bad in dec") -> Good in dec | CF48: =IF(AND(CA48="GOOD IN NOV",CE48="Bad in dec"),"CONNECT","NOT CONNECT") -> NOT CONNECT
